Configuration summary:
Available actions: web_search, geolocate, image_search, reverse_search
llm: gemini-2.0-flash-lite-001
benchmark_name: gaza_israel
tools_config:
    searcher:
        limit_per_search: 3
        search_engine_config:
            google: null
            google_vision: null
    geolocator: null
experiment_name: no_image_search
fact_checker_kwargs:
    decompose: false
    decontextualize: false
    filter_check_worthy: false
    interpret: false
    max_iterations: 3
    max_result_len: 64000
    procedure_variant: summary/dynamic
llm_kwargs:
    temperature: 0.01
benchmark_kwargs:
    variant: dev
allowed_actions:
- web_search
- reverse_search
- geolocate
n_samples: null
sample_ids: null
random_sampling: false
print_log_level: info
continue_experiment_dir: null
n_workers: 4

Started Worker 0 with PID 50.
Started Worker 1 with PID 51.
Started Worker 2 with PID 52.
Started Worker 3 with PID 53.
Worker 0 encountered an error while processing claim 18:
Traceback (most recent call last):
  File "/usr/local/lib/python3.10/site-packages/google/api_core/grpc_helpers.py", line 76, in error_remapped_callable
    return callable_(*args, **kwargs)
  File "/usr/local/lib/python3.10/site-packages/grpc/_channel.py", line 1181, in __call__
    return _end_unary_response_blocking(state, call, False, None)
  File "/usr/local/lib/python3.10/site-packages/grpc/_channel.py", line 1006, in _end_unary_response_blocking
    raise _InactiveRpcError(state)  # pytype: disable=not-instantiable
grpc._channel._InactiveRpcError: <_InactiveRpcError of RPC that terminated with:
	status = StatusCode.UNAVAILABLE
	details = "GOAWAY received; Error code: 0; Debug Text: session_timed_out"
	debug_error_string = "UNKNOWN:Error received from peer  {grpc_message:"GOAWAY received; Error code: 0; Debug Text: session_timed_out", grpc_status:14, created_time:"2025-08-30T23:26:50.255954971+00:00"}"
>

The above exception was the direct cause of the following exception:

Traceback (most recent call last):
  File "/defame/defame/eval/evaluate.py", line 847, in fact_check
    _, docs, metas = fc.check_content(content)
  File "/defame/defame/fact_checker.py", line 126, in check_content
    doc, meta = self.verify_claim(claim)
  File "/defame/defame/fact_checker.py", line 160, in verify_claim
    label, meta = self.procedure.apply_to(doc)
  File "/defame/defame/procedure/variants/summary_based/dynamic.py", line 23, in apply_to
    evidences = self.actor.perform(actions, doc)
  File "/defame/defame/modules/actor.py", line 19, in perform
    all_evidence.append(self._perform_single(action, doc, summarize=summarize))
  File "/defame/defame/modules/actor.py", line 24, in _perform_single
    return tool.perform(action, summarize=summarize, doc=doc)
  File "/defame/defame/tools/tool.py", line 19, in perform
    result = self._perform(action)
  File "/defame/defame/tools/search/searcher.py", line 124, in _perform
    return self.search(query)
  File "/defame/defame/tools/search/searcher.py", line 132, in search
    search_result = search_engine.search(query)
  File "/defame/defame/tools/search/remote_search_api.py", line 160, in search
    search_result = super().search(query)
  File "/defame/defame/tools/search/search_api.py", line 28, in search
    return self._call_api(query)
  File "/defame/defame/tools/search/google_vision_api.py", line 33, in _call_api
    response = self.client.web_detection(image=image)
  File "/usr/local/lib/python3.10/site-packages/google/cloud/vision_helpers/decorators.py", line 112, in inner
    response = self.annotate_image(
  File "/usr/local/lib/python3.10/site-packages/google/cloud/vision_helpers/__init__.py", line 76, in annotate_image
    r = self.batch_annotate_images(
  File "/usr/local/lib/python3.10/site-packages/google/cloud/vision_v1/services/image_annotator/client.py", line 802, in batch_annotate_images
    response = rpc(
  File "/usr/local/lib/python3.10/site-packages/google/api_core/gapic_v1/method.py", line 131, in __call__
    return wrapped_func(*args, **kwargs)
  File "/usr/local/lib/python3.10/site-packages/google/api_core/grpc_helpers.py", line 78, in error_remapped_callable
    raise exceptions.from_grpc_error(exc) from exc
google.api_core.exceptions.ServiceUnavailable: 503 GOAWAY received; Error code: 0; Debug Text: session_timed_out

All workers are terminated.
All outputs saved in /defame/out/ukraine_russia/gaza_israel/summary/dynamic/gemini-2.0-flash-lite-001/2025-08-30_23-13 no_image_search.
